<?xml version="1.0" encoding="UTF-8"?>
<!-- Generated by org.testng.reporters.JUnitReportReporter -->
<testsuite hostname="DESKTOP-FLAG05I" failures="12" tests="41" name="tests.RegisterTest" time="338.039" errors="1" timestamp="2024-11-06T01:04:08 EST" skipped="13">
  <testcase classname="tests.RegisterTest" name="verifyRegisteringAccountUsingMandatoryFields_Test" time="8.482"/>
  <testcase classname="tests.RegisterTest" name="verifyRegisteringAccountUsingNonMandatoryFields_Test" time="8.438"/>
  <testcase classname="tests.RegisterTest" name="verifyRegisteringAccountWithoutAnyDetails_Test" time="7.826"/>
  <testcase classname="tests.RegisterTest" name="verifyRegisteringAccountWithYesSelectedForNewsletter_Test" time="8.695"/>
  <testcase classname="tests.RegisterTest" name="verifyRegisteringAccountWithNoSelectedForNewsletter_Test" time="8.961"/>
  <testcase classname="tests.RegisterTest" name="verifyDiffWaysNavigatingToRegisterAccount_Test" time="7.361"/>
  <testcase classname="tests.RegisterTest" name="verifyRegisteringWithDifferentPassAndConfirmPass_Test" time="8.887"/>
  <testcase classname="tests.RegisterTest" name="verifyRegisteringWithExistingDetails_Test" time="8.244"/>
  <testcase classname="tests.RegisterTest" name="verifyInvalidEmailTooltipMsgs_Test" time="7.453"/>
  <testcase classname="tests.RegisterTest" name="verifyUserCannotUseInvalidPhoneNumberForRegistration_Test" time="8.269">
    <failure message="did not expect [Your Account Has Been Created!] but found [Your Account Has Been Created!]" type="java.lang.AssertionError">
      <![CDATA[java.lang.AssertionError: did not expect [Your Account Has Been Created!] but found [Your Account Has Been Created!]
at org.testng.Assert.fail(Assert.java:111)
at org.testng.Assert.failEquals(Assert.java:1582)
at org.testng.Assert.assertNotEqualsImpl(Assert.java:157)
at org.testng.Assert.assertNotEquals(Assert.java:2201)
at org.testng.Assert.assertNotEquals(Assert.java:2223)
at tests.RegisterTest.verifyUserCannotUseInvalidPhoneNumberForRegistration_Test(RegisterTest.java:170)
at java.base/jdk.internal.reflect.DirectMethodHandleAccessor.invoke(DirectMethodHandleAccessor.java:103)
at java.base/java.lang.reflect.Method.invoke(Method.java:580)
at org.testng.internal.invokers.MethodInvocationHelper.invokeMethod(MethodInvocationHelper.java:141)
at org.testng.internal.invokers.TestInvoker.invokeMethod(TestInvoker.java:686)
at org.testng.internal.invokers.TestInvoker.retryFailed(TestInvoker.java:269)
at org.testng.internal.invokers.MethodRunner.runInSequence(MethodRunner.java:76)
at org.testng.internal.invokers.TestInvoker$MethodInvocationAgent.invoke(TestInvoker.java:992)
at org.testng.internal.invokers.TestInvoker.invokeTestMethods(TestInvoker.java:203)
at org.testng.internal.invokers.TestMethodWorker.invokeTestMethods(TestMethodWorker.java:154)
at org.testng.internal.invokers.TestMethodWorker.run(TestMethodWorker.java:134)
at java.base/java.util.ArrayList.forEach(ArrayList.java:1596)
at org.testng.TestRunner.privateRun(TestRunner.java:739)
at org.testng.TestRunner.run(TestRunner.java:614)
at org.testng.SuiteRunner.runTest(SuiteRunner.java:421)
at org.testng.SuiteRunner.runSequentially(SuiteRunner.java:413)
at org.testng.SuiteRunner.privateRun(SuiteRunner.java:373)
at org.testng.SuiteRunner.run(SuiteRunner.java:312)
at org.testng.SuiteRunnerWorker.runSuite(SuiteRunnerWorker.java:52)
at org.testng.SuiteRunnerWorker.run(SuiteRunnerWorker.java:95)
at org.testng.TestNG.runSuitesSequentially(TestNG.java:1274)
at org.testng.TestNG.runSuitesLocally(TestNG.java:1208)
at org.testng.TestNG.runSuites(TestNG.java:1112)
at org.testng.TestNG.run(TestNG.java:1079)
at org.testng.remote.AbstractRemoteTestNG.run(AbstractRemoteTestNG.java:115)
at org.testng.remote.RemoteTestNG.initAndRun(RemoteTestNG.java:293)
at org.testng.remote.RemoteTestNG.main(RemoteTestNG.java:91)
]]>
    </failure>
  </testcase> <!-- verifyUserCannotUseInvalidPhoneNumberForRegistration_Test -->
  <testcase classname="tests.RegisterTest" name="verifyUserCannotUseInvalidPhoneNumberForRegistration_Test" time="9.134">
    <skipped/>
  </testcase> <!-- verifyUserCannotUseInvalidPhoneNumberForRegistration_Test -->
  <testcase classname="tests.RegisterTest" name="verifyUserCannotUseInvalidPhoneNumberForRegistration_Test" time="8.880">
    <failure message="did not expect [Your Account Has Been Created!] but found [Your Account Has Been Created!]" type="java.lang.AssertionError">
      <![CDATA[java.lang.AssertionError: did not expect [Your Account Has Been Created!] but found [Your Account Has Been Created!]
at org.testng.Assert.fail(Assert.java:111)
at org.testng.Assert.failEquals(Assert.java:1582)
at org.testng.Assert.assertNotEqualsImpl(Assert.java:157)
at org.testng.Assert.assertNotEquals(Assert.java:2201)
at org.testng.Assert.assertNotEquals(Assert.java:2223)
at tests.RegisterTest.verifyUserCannotUseInvalidPhoneNumberForRegistration_Test(RegisterTest.java:170)
at java.base/jdk.internal.reflect.DirectMethodHandleAccessor.invoke(DirectMethodHandleAccessor.java:103)
at java.base/java.lang.reflect.Method.invoke(Method.java:580)
at org.testng.internal.invokers.MethodInvocationHelper.invokeMethod(MethodInvocationHelper.java:141)
at org.testng.internal.invokers.TestInvoker.invokeMethod(TestInvoker.java:686)
at org.testng.internal.invokers.TestInvoker.retryFailed(TestInvoker.java:269)
at org.testng.internal.invokers.MethodRunner.runInSequence(MethodRunner.java:76)
at org.testng.internal.invokers.TestInvoker$MethodInvocationAgent.invoke(TestInvoker.java:992)
at org.testng.internal.invokers.TestInvoker.invokeTestMethods(TestInvoker.java:203)
at org.testng.internal.invokers.TestMethodWorker.invokeTestMethods(TestMethodWorker.java:154)
at org.testng.internal.invokers.TestMethodWorker.run(TestMethodWorker.java:134)
at java.base/java.util.ArrayList.forEach(ArrayList.java:1596)
at org.testng.TestRunner.privateRun(TestRunner.java:739)
at org.testng.TestRunner.run(TestRunner.java:614)
at org.testng.SuiteRunner.runTest(SuiteRunner.java:421)
at org.testng.SuiteRunner.runSequentially(SuiteRunner.java:413)
at org.testng.SuiteRunner.privateRun(SuiteRunner.java:373)
at org.testng.SuiteRunner.run(SuiteRunner.java:312)
at org.testng.SuiteRunnerWorker.runSuite(SuiteRunnerWorker.java:52)
at org.testng.SuiteRunnerWorker.run(SuiteRunnerWorker.java:95)
at org.testng.TestNG.runSuitesSequentially(TestNG.java:1274)
at org.testng.TestNG.runSuitesLocally(TestNG.java:1208)
at org.testng.TestNG.runSuites(TestNG.java:1112)
at org.testng.TestNG.run(TestNG.java:1079)
at org.testng.remote.AbstractRemoteTestNG.run(AbstractRemoteTestNG.java:115)
at org.testng.remote.RemoteTestNG.initAndRun(RemoteTestNG.java:293)
at org.testng.remote.RemoteTestNG.main(RemoteTestNG.java:91)
]]>
    </failure>
  </testcase> <!-- verifyUserCannotUseInvalidPhoneNumberForRegistration_Test -->
  <testcase classname="tests.RegisterTest" name="verifyUserCannotUseInvalidPhoneNumberForRegistration_Test" time="8.421">
    <skipped/>
  </testcase> <!-- verifyUserCannotUseInvalidPhoneNumberForRegistration_Test -->
  <testcase classname="tests.RegisterTest" name="verifyUserCannotUseInvalidPhoneNumberForRegistration_Test" time="8.909">
    <failure message="did not expect [Your Account Has Been Created!] but found [Your Account Has Been Created!]" type="java.lang.AssertionError">
      <![CDATA[java.lang.AssertionError: did not expect [Your Account Has Been Created!] but found [Your Account Has Been Created!]
at org.testng.Assert.fail(Assert.java:111)
at org.testng.Assert.failEquals(Assert.java:1582)
at org.testng.Assert.assertNotEqualsImpl(Assert.java:157)
at org.testng.Assert.assertNotEquals(Assert.java:2201)
at org.testng.Assert.assertNotEquals(Assert.java:2223)
at tests.RegisterTest.verifyUserCannotUseInvalidPhoneNumberForRegistration_Test(RegisterTest.java:170)
at java.base/jdk.internal.reflect.DirectMethodHandleAccessor.invoke(DirectMethodHandleAccessor.java:103)
at java.base/java.lang.reflect.Method.invoke(Method.java:580)
at org.testng.internal.invokers.MethodInvocationHelper.invokeMethod(MethodInvocationHelper.java:141)
at org.testng.internal.invokers.TestInvoker.invokeMethod(TestInvoker.java:686)
at org.testng.internal.invokers.TestInvoker.retryFailed(TestInvoker.java:269)
at org.testng.internal.invokers.MethodRunner.runInSequence(MethodRunner.java:76)
at org.testng.internal.invokers.TestInvoker$MethodInvocationAgent.invoke(TestInvoker.java:992)
at org.testng.internal.invokers.TestInvoker.invokeTestMethods(TestInvoker.java:203)
at org.testng.internal.invokers.TestMethodWorker.invokeTestMethods(TestMethodWorker.java:154)
at org.testng.internal.invokers.TestMethodWorker.run(TestMethodWorker.java:134)
at java.base/java.util.ArrayList.forEach(ArrayList.java:1596)
at org.testng.TestRunner.privateRun(TestRunner.java:739)
at org.testng.TestRunner.run(TestRunner.java:614)
at org.testng.SuiteRunner.runTest(SuiteRunner.java:421)
at org.testng.SuiteRunner.runSequentially(SuiteRunner.java:413)
at org.testng.SuiteRunner.privateRun(SuiteRunner.java:373)
at org.testng.SuiteRunner.run(SuiteRunner.java:312)
at org.testng.SuiteRunnerWorker.runSuite(SuiteRunnerWorker.java:52)
at org.testng.SuiteRunnerWorker.run(SuiteRunnerWorker.java:95)
at org.testng.TestNG.runSuitesSequentially(TestNG.java:1274)
at org.testng.TestNG.runSuitesLocally(TestNG.java:1208)
at org.testng.TestNG.runSuites(TestNG.java:1112)
at org.testng.TestNG.run(TestNG.java:1079)
at org.testng.remote.AbstractRemoteTestNG.run(AbstractRemoteTestNG.java:115)
at org.testng.remote.RemoteTestNG.initAndRun(RemoteTestNG.java:293)
at org.testng.remote.RemoteTestNG.main(RemoteTestNG.java:91)
]]>
    </failure>
  </testcase> <!-- verifyUserCannotUseInvalidPhoneNumberForRegistration_Test -->
  <testcase classname="tests.RegisterTest" name="verifyUserCannotUseInvalidPhoneNumberForRegistration_Test" time="8.592">
    <skipped/>
  </testcase> <!-- verifyUserCannotUseInvalidPhoneNumberForRegistration_Test -->
  <testcase classname="tests.RegisterTest" name="verifyUserCannotUseInvalidPhoneNumberForRegistration_Test" time="8.577">
    <skipped/>
  </testcase> <!-- verifyUserCannotUseInvalidPhoneNumberForRegistration_Test -->
  <testcase classname="tests.RegisterTest" name="verifyUserCannotUseInvalidPhoneNumberForRegistration_Test" time="8.618">
    <failure message="did not expect [Your Account Has Been Created!] but found [Your Account Has Been Created!]" type="java.lang.AssertionError">
      <![CDATA[java.lang.AssertionError: did not expect [Your Account Has Been Created!] but found [Your Account Has Been Created!]
at org.testng.Assert.fail(Assert.java:111)
at org.testng.Assert.failEquals(Assert.java:1582)
at org.testng.Assert.assertNotEqualsImpl(Assert.java:157)
at org.testng.Assert.assertNotEquals(Assert.java:2201)
at org.testng.Assert.assertNotEquals(Assert.java:2223)
at tests.RegisterTest.verifyUserCannotUseInvalidPhoneNumberForRegistration_Test(RegisterTest.java:170)
at java.base/jdk.internal.reflect.DirectMethodHandleAccessor.invoke(DirectMethodHandleAccessor.java:103)
at java.base/java.lang.reflect.Method.invoke(Method.java:580)
at org.testng.internal.invokers.MethodInvocationHelper.invokeMethod(MethodInvocationHelper.java:141)
at org.testng.internal.invokers.TestInvoker.invokeMethod(TestInvoker.java:686)
at org.testng.internal.invokers.TestInvoker.retryFailed(TestInvoker.java:269)
at org.testng.internal.invokers.MethodRunner.runInSequence(MethodRunner.java:76)
at org.testng.internal.invokers.TestInvoker$MethodInvocationAgent.invoke(TestInvoker.java:992)
at org.testng.internal.invokers.TestInvoker.invokeTestMethods(TestInvoker.java:203)
at org.testng.internal.invokers.TestMethodWorker.invokeTestMethods(TestMethodWorker.java:154)
at org.testng.internal.invokers.TestMethodWorker.run(TestMethodWorker.java:134)
at java.base/java.util.ArrayList.forEach(ArrayList.java:1596)
at org.testng.TestRunner.privateRun(TestRunner.java:739)
at org.testng.TestRunner.run(TestRunner.java:614)
at org.testng.SuiteRunner.runTest(SuiteRunner.java:421)
at org.testng.SuiteRunner.runSequentially(SuiteRunner.java:413)
at org.testng.SuiteRunner.privateRun(SuiteRunner.java:373)
at org.testng.SuiteRunner.run(SuiteRunner.java:312)
at org.testng.SuiteRunnerWorker.runSuite(SuiteRunnerWorker.java:52)
at org.testng.SuiteRunnerWorker.run(SuiteRunnerWorker.java:95)
at org.testng.TestNG.runSuitesSequentially(TestNG.java:1274)
at org.testng.TestNG.runSuitesLocally(TestNG.java:1208)
at org.testng.TestNG.runSuites(TestNG.java:1112)
at org.testng.TestNG.run(TestNG.java:1079)
at org.testng.remote.AbstractRemoteTestNG.run(AbstractRemoteTestNG.java:115)
at org.testng.remote.RemoteTestNG.initAndRun(RemoteTestNG.java:293)
at org.testng.remote.RemoteTestNG.main(RemoteTestNG.java:91)
]]>
    </failure>
  </testcase> <!-- verifyUserCannotUseInvalidPhoneNumberForRegistration_Test -->
  <testcase classname="tests.RegisterTest" name="verifyUserCannotUseInvalidPhoneNumberForRegistration_Test" time="8.782">
    <failure message="did not expect [Your Account Has Been Created!] but found [Your Account Has Been Created!]" type="java.lang.AssertionError">
      <![CDATA[java.lang.AssertionError: did not expect [Your Account Has Been Created!] but found [Your Account Has Been Created!]
at org.testng.Assert.fail(Assert.java:111)
at org.testng.Assert.failEquals(Assert.java:1582)
at org.testng.Assert.assertNotEqualsImpl(Assert.java:157)
at org.testng.Assert.assertNotEquals(Assert.java:2201)
at org.testng.Assert.assertNotEquals(Assert.java:2223)
at tests.RegisterTest.verifyUserCannotUseInvalidPhoneNumberForRegistration_Test(RegisterTest.java:170)
at java.base/jdk.internal.reflect.DirectMethodHandleAccessor.invoke(DirectMethodHandleAccessor.java:103)
at java.base/java.lang.reflect.Method.invoke(Method.java:580)
at org.testng.internal.invokers.MethodInvocationHelper.invokeMethod(MethodInvocationHelper.java:141)
at org.testng.internal.invokers.TestInvoker.invokeMethod(TestInvoker.java:686)
at org.testng.internal.invokers.TestInvoker.retryFailed(TestInvoker.java:269)
at org.testng.internal.invokers.MethodRunner.runInSequence(MethodRunner.java:76)
at org.testng.internal.invokers.TestInvoker$MethodInvocationAgent.invoke(TestInvoker.java:992)
at org.testng.internal.invokers.TestInvoker.invokeTestMethods(TestInvoker.java:203)
at org.testng.internal.invokers.TestMethodWorker.invokeTestMethods(TestMethodWorker.java:154)
at org.testng.internal.invokers.TestMethodWorker.run(TestMethodWorker.java:134)
at java.base/java.util.ArrayList.forEach(ArrayList.java:1596)
at org.testng.TestRunner.privateRun(TestRunner.java:739)
at org.testng.TestRunner.run(TestRunner.java:614)
at org.testng.SuiteRunner.runTest(SuiteRunner.java:421)
at org.testng.SuiteRunner.runSequentially(SuiteRunner.java:413)
at org.testng.SuiteRunner.privateRun(SuiteRunner.java:373)
at org.testng.SuiteRunner.run(SuiteRunner.java:312)
at org.testng.SuiteRunnerWorker.runSuite(SuiteRunnerWorker.java:52)
at org.testng.SuiteRunnerWorker.run(SuiteRunnerWorker.java:95)
at org.testng.TestNG.runSuitesSequentially(TestNG.java:1274)
at org.testng.TestNG.runSuitesLocally(TestNG.java:1208)
at org.testng.TestNG.runSuites(TestNG.java:1112)
at org.testng.TestNG.run(TestNG.java:1079)
at org.testng.remote.AbstractRemoteTestNG.run(AbstractRemoteTestNG.java:115)
at org.testng.remote.RemoteTestNG.initAndRun(RemoteTestNG.java:293)
at org.testng.remote.RemoteTestNG.main(RemoteTestNG.java:91)
]]>
    </failure>
  </testcase> <!-- verifyUserCannotUseInvalidPhoneNumberForRegistration_Test -->
  <testcase classname="tests.RegisterTest" name="verifyUserCannotUseInvalidPhoneNumberForRegistration_Test" time="8.683">
    <skipped/>
  </testcase> <!-- verifyUserCannotUseInvalidPhoneNumberForRegistration_Test -->
  <testcase classname="tests.RegisterTest" name="verifyRegisterPagePlaceholders_Test" time="6.417"/>
  <testcase classname="tests.RegisterTest" name="verifyAsterickSymbolForMandatoryFields_Test" time="6.156"/>
  <testcase classname="tests.RegisterTest" name="verifyPasswordFieldFollowsComplexityStandards" time="8.796">
    <failure message="did not expect [Your Account Has Been Created!] but found [Your Account Has Been Created!]" type="java.lang.AssertionError">
      <![CDATA[java.lang.AssertionError: did not expect [Your Account Has Been Created!] but found [Your Account Has Been Created!]
at org.testng.Assert.fail(Assert.java:111)
at org.testng.Assert.failEquals(Assert.java:1582)
at org.testng.Assert.assertNotEqualsImpl(Assert.java:157)
at org.testng.Assert.assertNotEquals(Assert.java:2201)
at org.testng.Assert.assertNotEquals(Assert.java:2223)
at tests.RegisterTest.verifyPasswordFieldFollowsComplexityStandards(RegisterTest.java:208)
at java.base/jdk.internal.reflect.DirectMethodHandleAccessor.invoke(DirectMethodHandleAccessor.java:103)
at java.base/java.lang.reflect.Method.invoke(Method.java:580)
at org.testng.internal.invokers.MethodInvocationHelper.invokeMethod(MethodInvocationHelper.java:141)
at org.testng.internal.invokers.TestInvoker.invokeMethod(TestInvoker.java:686)
at org.testng.internal.invokers.TestInvoker.retryFailed(TestInvoker.java:269)
at org.testng.internal.invokers.MethodRunner.runInSequence(MethodRunner.java:76)
at org.testng.internal.invokers.TestInvoker$MethodInvocationAgent.invoke(TestInvoker.java:992)
at org.testng.internal.invokers.TestInvoker.invokeTestMethods(TestInvoker.java:203)
at org.testng.internal.invokers.TestMethodWorker.invokeTestMethods(TestMethodWorker.java:154)
at org.testng.internal.invokers.TestMethodWorker.run(TestMethodWorker.java:134)
at java.base/java.util.ArrayList.forEach(ArrayList.java:1596)
at org.testng.TestRunner.privateRun(TestRunner.java:739)
at org.testng.TestRunner.run(TestRunner.java:614)
at org.testng.SuiteRunner.runTest(SuiteRunner.java:421)
at org.testng.SuiteRunner.runSequentially(SuiteRunner.java:413)
at org.testng.SuiteRunner.privateRun(SuiteRunner.java:373)
at org.testng.SuiteRunner.run(SuiteRunner.java:312)
at org.testng.SuiteRunnerWorker.runSuite(SuiteRunnerWorker.java:52)
at org.testng.SuiteRunnerWorker.run(SuiteRunnerWorker.java:95)
at org.testng.TestNG.runSuitesSequentially(TestNG.java:1274)
at org.testng.TestNG.runSuitesLocally(TestNG.java:1208)
at org.testng.TestNG.runSuites(TestNG.java:1112)
at org.testng.TestNG.run(TestNG.java:1079)
at org.testng.remote.AbstractRemoteTestNG.run(AbstractRemoteTestNG.java:115)
at org.testng.remote.RemoteTestNG.initAndRun(RemoteTestNG.java:293)
at org.testng.remote.RemoteTestNG.main(RemoteTestNG.java:91)
]]>
    </failure>
  </testcase> <!-- verifyPasswordFieldFollowsComplexityStandards -->
  <testcase classname="tests.RegisterTest" name="verifyPasswordFieldFollowsComplexityStandards" time="9.767">
    <skipped/>
  </testcase> <!-- verifyPasswordFieldFollowsComplexityStandards -->
  <testcase classname="tests.RegisterTest" name="verifyPasswordFieldFollowsComplexityStandards" time="8.737">
    <failure message="did not expect [Your Account Has Been Created!] but found [Your Account Has Been Created!]" type="java.lang.AssertionError">
      <![CDATA[java.lang.AssertionError: did not expect [Your Account Has Been Created!] but found [Your Account Has Been Created!]
at org.testng.Assert.fail(Assert.java:111)
at org.testng.Assert.failEquals(Assert.java:1582)
at org.testng.Assert.assertNotEqualsImpl(Assert.java:157)
at org.testng.Assert.assertNotEquals(Assert.java:2201)
at org.testng.Assert.assertNotEquals(Assert.java:2223)
at tests.RegisterTest.verifyPasswordFieldFollowsComplexityStandards(RegisterTest.java:208)
at java.base/jdk.internal.reflect.DirectMethodHandleAccessor.invoke(DirectMethodHandleAccessor.java:103)
at java.base/java.lang.reflect.Method.invoke(Method.java:580)
at org.testng.internal.invokers.MethodInvocationHelper.invokeMethod(MethodInvocationHelper.java:141)
at org.testng.internal.invokers.TestInvoker.invokeMethod(TestInvoker.java:686)
at org.testng.internal.invokers.TestInvoker.retryFailed(TestInvoker.java:269)
at org.testng.internal.invokers.MethodRunner.runInSequence(MethodRunner.java:76)
at org.testng.internal.invokers.TestInvoker$MethodInvocationAgent.invoke(TestInvoker.java:992)
at org.testng.internal.invokers.TestInvoker.invokeTestMethods(TestInvoker.java:203)
at org.testng.internal.invokers.TestMethodWorker.invokeTestMethods(TestMethodWorker.java:154)
at org.testng.internal.invokers.TestMethodWorker.run(TestMethodWorker.java:134)
at java.base/java.util.ArrayList.forEach(ArrayList.java:1596)
at org.testng.TestRunner.privateRun(TestRunner.java:739)
at org.testng.TestRunner.run(TestRunner.java:614)
at org.testng.SuiteRunner.runTest(SuiteRunner.java:421)
at org.testng.SuiteRunner.runSequentially(SuiteRunner.java:413)
at org.testng.SuiteRunner.privateRun(SuiteRunner.java:373)
at org.testng.SuiteRunner.run(SuiteRunner.java:312)
at org.testng.SuiteRunnerWorker.runSuite(SuiteRunnerWorker.java:52)
at org.testng.SuiteRunnerWorker.run(SuiteRunnerWorker.java:95)
at org.testng.TestNG.runSuitesSequentially(TestNG.java:1274)
at org.testng.TestNG.runSuitesLocally(TestNG.java:1208)
at org.testng.TestNG.runSuites(TestNG.java:1112)
at org.testng.TestNG.run(TestNG.java:1079)
at org.testng.remote.AbstractRemoteTestNG.run(AbstractRemoteTestNG.java:115)
at org.testng.remote.RemoteTestNG.initAndRun(RemoteTestNG.java:293)
at org.testng.remote.RemoteTestNG.main(RemoteTestNG.java:91)
]]>
    </failure>
  </testcase> <!-- verifyPasswordFieldFollowsComplexityStandards -->
  <testcase classname="tests.RegisterTest" name="verifyPasswordFieldFollowsComplexityStandards" time="9.570">
    <failure message="did not expect [Your Account Has Been Created!] but found [Your Account Has Been Created!]" type="java.lang.AssertionError">
      <![CDATA[java.lang.AssertionError: did not expect [Your Account Has Been Created!] but found [Your Account Has Been Created!]
at org.testng.Assert.fail(Assert.java:111)
at org.testng.Assert.failEquals(Assert.java:1582)
at org.testng.Assert.assertNotEqualsImpl(Assert.java:157)
at org.testng.Assert.assertNotEquals(Assert.java:2201)
at org.testng.Assert.assertNotEquals(Assert.java:2223)
at tests.RegisterTest.verifyPasswordFieldFollowsComplexityStandards(RegisterTest.java:208)
at java.base/jdk.internal.reflect.DirectMethodHandleAccessor.invoke(DirectMethodHandleAccessor.java:103)
at java.base/java.lang.reflect.Method.invoke(Method.java:580)
at org.testng.internal.invokers.MethodInvocationHelper.invokeMethod(MethodInvocationHelper.java:141)
at org.testng.internal.invokers.TestInvoker.invokeMethod(TestInvoker.java:686)
at org.testng.internal.invokers.TestInvoker.retryFailed(TestInvoker.java:269)
at org.testng.internal.invokers.MethodRunner.runInSequence(MethodRunner.java:76)
at org.testng.internal.invokers.TestInvoker$MethodInvocationAgent.invoke(TestInvoker.java:992)
at org.testng.internal.invokers.TestInvoker.invokeTestMethods(TestInvoker.java:203)
at org.testng.internal.invokers.TestMethodWorker.invokeTestMethods(TestMethodWorker.java:154)
at org.testng.internal.invokers.TestMethodWorker.run(TestMethodWorker.java:134)
at java.base/java.util.ArrayList.forEach(ArrayList.java:1596)
at org.testng.TestRunner.privateRun(TestRunner.java:739)
at org.testng.TestRunner.run(TestRunner.java:614)
at org.testng.SuiteRunner.runTest(SuiteRunner.java:421)
at org.testng.SuiteRunner.runSequentially(SuiteRunner.java:413)
at org.testng.SuiteRunner.privateRun(SuiteRunner.java:373)
at org.testng.SuiteRunner.run(SuiteRunner.java:312)
at org.testng.SuiteRunnerWorker.runSuite(SuiteRunnerWorker.java:52)
at org.testng.SuiteRunnerWorker.run(SuiteRunnerWorker.java:95)
at org.testng.TestNG.runSuitesSequentially(TestNG.java:1274)
at org.testng.TestNG.runSuitesLocally(TestNG.java:1208)
at org.testng.TestNG.runSuites(TestNG.java:1112)
at org.testng.TestNG.run(TestNG.java:1079)
at org.testng.remote.AbstractRemoteTestNG.run(AbstractRemoteTestNG.java:115)
at org.testng.remote.RemoteTestNG.initAndRun(RemoteTestNG.java:293)
at org.testng.remote.RemoteTestNG.main(RemoteTestNG.java:91)
]]>
    </failure>
  </testcase> <!-- verifyPasswordFieldFollowsComplexityStandards -->
  <testcase classname="tests.RegisterTest" name="verifyPasswordFieldFollowsComplexityStandards" time="8.422">
    <skipped/>
  </testcase> <!-- verifyPasswordFieldFollowsComplexityStandards -->
  <testcase classname="tests.RegisterTest" name="verifyPasswordFieldFollowsComplexityStandards" time="8.516">
    <skipped/>
  </testcase> <!-- verifyPasswordFieldFollowsComplexityStandards -->
  <testcase classname="tests.RegisterTest" name="verifyPasswordFieldFollowsComplexityStandards" time="8.614">
    <failure message="did not expect [Your Account Has Been Created!] but found [Your Account Has Been Created!]" type="java.lang.AssertionError">
      <![CDATA[java.lang.AssertionError: did not expect [Your Account Has Been Created!] but found [Your Account Has Been Created!]
at org.testng.Assert.fail(Assert.java:111)
at org.testng.Assert.failEquals(Assert.java:1582)
at org.testng.Assert.assertNotEqualsImpl(Assert.java:157)
at org.testng.Assert.assertNotEquals(Assert.java:2201)
at org.testng.Assert.assertNotEquals(Assert.java:2223)
at tests.RegisterTest.verifyPasswordFieldFollowsComplexityStandards(RegisterTest.java:208)
at java.base/jdk.internal.reflect.DirectMethodHandleAccessor.invoke(DirectMethodHandleAccessor.java:103)
at java.base/java.lang.reflect.Method.invoke(Method.java:580)
at org.testng.internal.invokers.MethodInvocationHelper.invokeMethod(MethodInvocationHelper.java:141)
at org.testng.internal.invokers.TestInvoker.invokeMethod(TestInvoker.java:686)
at org.testng.internal.invokers.TestInvoker.retryFailed(TestInvoker.java:269)
at org.testng.internal.invokers.MethodRunner.runInSequence(MethodRunner.java:76)
at org.testng.internal.invokers.TestInvoker$MethodInvocationAgent.invoke(TestInvoker.java:992)
at org.testng.internal.invokers.TestInvoker.invokeTestMethods(TestInvoker.java:203)
at org.testng.internal.invokers.TestMethodWorker.invokeTestMethods(TestMethodWorker.java:154)
at org.testng.internal.invokers.TestMethodWorker.run(TestMethodWorker.java:134)
at java.base/java.util.ArrayList.forEach(ArrayList.java:1596)
at org.testng.TestRunner.privateRun(TestRunner.java:739)
at org.testng.TestRunner.run(TestRunner.java:614)
at org.testng.SuiteRunner.runTest(SuiteRunner.java:421)
at org.testng.SuiteRunner.runSequentially(SuiteRunner.java:413)
at org.testng.SuiteRunner.privateRun(SuiteRunner.java:373)
at org.testng.SuiteRunner.run(SuiteRunner.java:312)
at org.testng.SuiteRunnerWorker.runSuite(SuiteRunnerWorker.java:52)
at org.testng.SuiteRunnerWorker.run(SuiteRunnerWorker.java:95)
at org.testng.TestNG.runSuitesSequentially(TestNG.java:1274)
at org.testng.TestNG.runSuitesLocally(TestNG.java:1208)
at org.testng.TestNG.runSuites(TestNG.java:1112)
at org.testng.TestNG.run(TestNG.java:1079)
at org.testng.remote.AbstractRemoteTestNG.run(AbstractRemoteTestNG.java:115)
at org.testng.remote.RemoteTestNG.initAndRun(RemoteTestNG.java:293)
at org.testng.remote.RemoteTestNG.main(RemoteTestNG.java:91)
]]>
    </failure>
  </testcase> <!-- verifyPasswordFieldFollowsComplexityStandards -->
  <testcase classname="tests.RegisterTest" name="verifyPasswordFieldFollowsComplexityStandards" time="8.278">
    <failure message="did not expect [Your Account Has Been Created!] but found [Your Account Has Been Created!]" type="java.lang.AssertionError">
      <![CDATA[java.lang.AssertionError: did not expect [Your Account Has Been Created!] but found [Your Account Has Been Created!]
at org.testng.Assert.fail(Assert.java:111)
at org.testng.Assert.failEquals(Assert.java:1582)
at org.testng.Assert.assertNotEqualsImpl(Assert.java:157)
at org.testng.Assert.assertNotEquals(Assert.java:2201)
at org.testng.Assert.assertNotEquals(Assert.java:2223)
at tests.RegisterTest.verifyPasswordFieldFollowsComplexityStandards(RegisterTest.java:208)
at java.base/jdk.internal.reflect.DirectMethodHandleAccessor.invoke(DirectMethodHandleAccessor.java:103)
at java.base/java.lang.reflect.Method.invoke(Method.java:580)
at org.testng.internal.invokers.MethodInvocationHelper.invokeMethod(MethodInvocationHelper.java:141)
at org.testng.internal.invokers.TestInvoker.invokeMethod(TestInvoker.java:686)
at org.testng.internal.invokers.TestInvoker.retryFailed(TestInvoker.java:269)
at org.testng.internal.invokers.MethodRunner.runInSequence(MethodRunner.java:76)
at org.testng.internal.invokers.TestInvoker$MethodInvocationAgent.invoke(TestInvoker.java:992)
at org.testng.internal.invokers.TestInvoker.invokeTestMethods(TestInvoker.java:203)
at org.testng.internal.invokers.TestMethodWorker.invokeTestMethods(TestMethodWorker.java:154)
at org.testng.internal.invokers.TestMethodWorker.run(TestMethodWorker.java:134)
at java.base/java.util.ArrayList.forEach(ArrayList.java:1596)
at org.testng.TestRunner.privateRun(TestRunner.java:739)
at org.testng.TestRunner.run(TestRunner.java:614)
at org.testng.SuiteRunner.runTest(SuiteRunner.java:421)
at org.testng.SuiteRunner.runSequentially(SuiteRunner.java:413)
at org.testng.SuiteRunner.privateRun(SuiteRunner.java:373)
at org.testng.SuiteRunner.run(SuiteRunner.java:312)
at org.testng.SuiteRunnerWorker.runSuite(SuiteRunnerWorker.java:52)
at org.testng.SuiteRunnerWorker.run(SuiteRunnerWorker.java:95)
at org.testng.TestNG.runSuitesSequentially(TestNG.java:1274)
at org.testng.TestNG.runSuitesLocally(TestNG.java:1208)
at org.testng.TestNG.runSuites(TestNG.java:1112)
at org.testng.TestNG.run(TestNG.java:1079)
at org.testng.remote.AbstractRemoteTestNG.run(AbstractRemoteTestNG.java:115)
at org.testng.remote.RemoteTestNG.initAndRun(RemoteTestNG.java:293)
at org.testng.remote.RemoteTestNG.main(RemoteTestNG.java:91)
]]>
    </failure>
  </testcase> <!-- verifyPasswordFieldFollowsComplexityStandards -->
  <testcase classname="tests.RegisterTest" name="verifyPasswordFieldFollowsComplexityStandards" time="8.448">
    <failure message="did not expect [Your Account Has Been Created!] but found [Your Account Has Been Created!]" type="java.lang.AssertionError">
      <![CDATA[java.lang.AssertionError: did not expect [Your Account Has Been Created!] but found [Your Account Has Been Created!]
at org.testng.Assert.fail(Assert.java:111)
at org.testng.Assert.failEquals(Assert.java:1582)
at org.testng.Assert.assertNotEqualsImpl(Assert.java:157)
at org.testng.Assert.assertNotEquals(Assert.java:2201)
at org.testng.Assert.assertNotEquals(Assert.java:2223)
at tests.RegisterTest.verifyPasswordFieldFollowsComplexityStandards(RegisterTest.java:208)
at java.base/jdk.internal.reflect.DirectMethodHandleAccessor.invoke(DirectMethodHandleAccessor.java:103)
at java.base/java.lang.reflect.Method.invoke(Method.java:580)
at org.testng.internal.invokers.MethodInvocationHelper.invokeMethod(MethodInvocationHelper.java:141)
at org.testng.internal.invokers.TestInvoker.invokeMethod(TestInvoker.java:686)
at org.testng.internal.invokers.TestInvoker.retryFailed(TestInvoker.java:269)
at org.testng.internal.invokers.MethodRunner.runInSequence(MethodRunner.java:76)
at org.testng.internal.invokers.TestInvoker$MethodInvocationAgent.invoke(TestInvoker.java:992)
at org.testng.internal.invokers.TestInvoker.invokeTestMethods(TestInvoker.java:203)
at org.testng.internal.invokers.TestMethodWorker.invokeTestMethods(TestMethodWorker.java:154)
at org.testng.internal.invokers.TestMethodWorker.run(TestMethodWorker.java:134)
at java.base/java.util.ArrayList.forEach(ArrayList.java:1596)
at org.testng.TestRunner.privateRun(TestRunner.java:739)
at org.testng.TestRunner.run(TestRunner.java:614)
at org.testng.SuiteRunner.runTest(SuiteRunner.java:421)
at org.testng.SuiteRunner.runSequentially(SuiteRunner.java:413)
at org.testng.SuiteRunner.privateRun(SuiteRunner.java:373)
at org.testng.SuiteRunner.run(SuiteRunner.java:312)
at org.testng.SuiteRunnerWorker.runSuite(SuiteRunnerWorker.java:52)
at org.testng.SuiteRunnerWorker.run(SuiteRunnerWorker.java:95)
at org.testng.TestNG.runSuitesSequentially(TestNG.java:1274)
at org.testng.TestNG.runSuitesLocally(TestNG.java:1208)
at org.testng.TestNG.runSuites(TestNG.java:1112)
at org.testng.TestNG.run(TestNG.java:1079)
at org.testng.remote.AbstractRemoteTestNG.run(AbstractRemoteTestNG.java:115)
at org.testng.remote.RemoteTestNG.initAndRun(RemoteTestNG.java:293)
at org.testng.remote.RemoteTestNG.main(RemoteTestNG.java:91)
]]>
    </failure>
  </testcase> <!-- verifyPasswordFieldFollowsComplexityStandards -->
  <testcase classname="tests.RegisterTest" name="verifyPasswordFieldFollowsComplexityStandards" time="8.521">
    <skipped/>
  </testcase> <!-- verifyPasswordFieldFollowsComplexityStandards -->
  <testcase classname="tests.RegisterTest" name="verifyPasswordFieldFollowsComplexityStandards" time="8.911">
    <failure message="did not expect [Your Account Has Been Created!] but found [Your Account Has Been Created!]" type="java.lang.AssertionError">
      <![CDATA[java.lang.AssertionError: did not expect [Your Account Has Been Created!] but found [Your Account Has Been Created!]
at org.testng.Assert.fail(Assert.java:111)
at org.testng.Assert.failEquals(Assert.java:1582)
at org.testng.Assert.assertNotEqualsImpl(Assert.java:157)
at org.testng.Assert.assertNotEquals(Assert.java:2201)
at org.testng.Assert.assertNotEquals(Assert.java:2223)
at tests.RegisterTest.verifyPasswordFieldFollowsComplexityStandards(RegisterTest.java:208)
at java.base/jdk.internal.reflect.DirectMethodHandleAccessor.invoke(DirectMethodHandleAccessor.java:103)
at java.base/java.lang.reflect.Method.invoke(Method.java:580)
at org.testng.internal.invokers.MethodInvocationHelper.invokeMethod(MethodInvocationHelper.java:141)
at org.testng.internal.invokers.TestInvoker.invokeMethod(TestInvoker.java:686)
at org.testng.internal.invokers.TestInvoker.retryFailed(TestInvoker.java:269)
at org.testng.internal.invokers.MethodRunner.runInSequence(MethodRunner.java:76)
at org.testng.internal.invokers.TestInvoker$MethodInvocationAgent.invoke(TestInvoker.java:992)
at org.testng.internal.invokers.TestInvoker.invokeTestMethods(TestInvoker.java:203)
at org.testng.internal.invokers.TestMethodWorker.invokeTestMethods(TestMethodWorker.java:154)
at org.testng.internal.invokers.TestMethodWorker.run(TestMethodWorker.java:134)
at java.base/java.util.ArrayList.forEach(ArrayList.java:1596)
at org.testng.TestRunner.privateRun(TestRunner.java:739)
at org.testng.TestRunner.run(TestRunner.java:614)
at org.testng.SuiteRunner.runTest(SuiteRunner.java:421)
at org.testng.SuiteRunner.runSequentially(SuiteRunner.java:413)
at org.testng.SuiteRunner.privateRun(SuiteRunner.java:373)
at org.testng.SuiteRunner.run(SuiteRunner.java:312)
at org.testng.SuiteRunnerWorker.runSuite(SuiteRunnerWorker.java:52)
at org.testng.SuiteRunnerWorker.run(SuiteRunnerWorker.java:95)
at org.testng.TestNG.runSuitesSequentially(TestNG.java:1274)
at org.testng.TestNG.runSuitesLocally(TestNG.java:1208)
at org.testng.TestNG.runSuites(TestNG.java:1112)
at org.testng.TestNG.run(TestNG.java:1079)
at org.testng.remote.AbstractRemoteTestNG.run(AbstractRemoteTestNG.java:115)
at org.testng.remote.RemoteTestNG.initAndRun(RemoteTestNG.java:293)
at org.testng.remote.RemoteTestNG.main(RemoteTestNG.java:91)
]]>
    </failure>
  </testcase> <!-- verifyPasswordFieldFollowsComplexityStandards -->
  <testcase classname="tests.RegisterTest" name="verifyPasswordFieldFollowsComplexityStandards" time="8.659">
    <skipped/>
  </testcase> <!-- verifyPasswordFieldFollowsComplexityStandards -->
  <testcase classname="tests.RegisterTest" name="verifyPasswordFieldFollowsComplexityStandards" time="8.589">
    <skipped/>
  </testcase> <!-- verifyPasswordFieldFollowsComplexityStandards -->
  <testcase classname="tests.RegisterTest" name="verifyPasswordFieldFollowsComplexityStandards" time="9.201">
    <skipped/>
  </testcase> <!-- verifyPasswordFieldFollowsComplexityStandards -->
  <testcase classname="tests.RegisterTest" name="verifyPrivacyPolicyCheckboxNotCheckedByDefault" time="5.955"/>
  <testcase classname="tests.RegisterTest" name="verifyRegistrationWithoutSelectingPrivacyPolicy" time="8.816"/>
  <testcase classname="tests.RegisterTest" name="verifyPasswordAndConfirmPasswordAreHidden" time="6.320"/>
  <testcase classname="tests.RegisterTest" name="verifyRegistrationWithoutConfirmPasswordInput_Test" time="7.944"/>
  <testcase classname="tests.RegisterTest" name="verifyConfirmationEmailSentForSuccessfulRegistration" time="6.177">
    <error message="All mandatory fields must be provided." type="java.lang.IllegalArgumentException">
      <![CDATA[java.lang.IllegalArgumentException: All mandatory fields must be provided.
at pagesobjects.RegisterPage.registerAnAccount(RegisterPage.java:173)
at tests.RegisterTest.verifyConfirmationEmailSentForSuccessfulRegistration(RegisterTest.java:254)
at java.base/jdk.internal.reflect.DirectMethodHandleAccessor.invoke(DirectMethodHandleAccessor.java:103)
at java.base/java.lang.reflect.Method.invoke(Method.java:580)
at org.testng.internal.invokers.MethodInvocationHelper.invokeMethod(MethodInvocationHelper.java:141)
at org.testng.internal.invokers.TestInvoker.invokeMethod(TestInvoker.java:686)
at org.testng.internal.invokers.TestInvoker.retryFailed(TestInvoker.java:269)
at org.testng.internal.invokers.MethodRunner.runInSequence(MethodRunner.java:76)
at org.testng.internal.invokers.TestInvoker$MethodInvocationAgent.invoke(TestInvoker.java:992)
at org.testng.internal.invokers.TestInvoker.invokeTestMethods(TestInvoker.java:203)
at org.testng.internal.invokers.TestMethodWorker.invokeTestMethods(TestMethodWorker.java:154)
at org.testng.internal.invokers.TestMethodWorker.run(TestMethodWorker.java:134)
at java.base/java.util.ArrayList.forEach(ArrayList.java:1596)
at org.testng.TestRunner.privateRun(TestRunner.java:739)
at org.testng.TestRunner.run(TestRunner.java:614)
at org.testng.SuiteRunner.runTest(SuiteRunner.java:421)
at org.testng.SuiteRunner.runSequentially(SuiteRunner.java:413)
at org.testng.SuiteRunner.privateRun(SuiteRunner.java:373)
at org.testng.SuiteRunner.run(SuiteRunner.java:312)
at org.testng.SuiteRunnerWorker.runSuite(SuiteRunnerWorker.java:52)
at org.testng.SuiteRunnerWorker.run(SuiteRunnerWorker.java:95)
at org.testng.TestNG.runSuitesSequentially(TestNG.java:1274)
at org.testng.TestNG.runSuitesLocally(TestNG.java:1208)
at org.testng.TestNG.runSuites(TestNG.java:1112)
at org.testng.TestNG.run(TestNG.java:1079)
at org.testng.remote.AbstractRemoteTestNG.run(AbstractRemoteTestNG.java:115)
at org.testng.remote.RemoteTestNG.initAndRun(RemoteTestNG.java:293)
at org.testng.remote.RemoteTestNG.main(RemoteTestNG.java:91)
]]>
    </error>
  </testcase> <!-- verifyConfirmationEmailSentForSuccessfulRegistration -->
  <testcase classname="tests.RegisterTest" name="verifyConfirmationEmailSentForSuccessfulRegistration" time="6.013">
    <skipped/>
  </testcase> <!-- verifyConfirmationEmailSentForSuccessfulRegistration -->
</testsuite> <!-- tests.RegisterTest -->
